Workbook

Sheet Instructions
A1: Cyprus VAT working - instructions
A2: How the working is built, what you do each quarter, and how each part feeds the VAT 4 return.
B4: 1. What this working does
B5: It takes the full general ledger (GL) for the VAT quarter, gives every line a VAT treatment code (through the account mapping, or an override on the line), classifies the counterparty as Cyprus (CY), other EU member state (EU) or third country (3RD) and as inter-company (Y) or third party (N), converts foreign-currency amounts to EUR at the quarterly average ECB rate, and builds the VAT 4 return (Boxes 1-11B), the VIES summary, an inter-company analysis and reconciliations to the VAT control accounts.
B6: All results are Excel formulas. Change a mapping, a country or a rate and every sheet updates.
B8: 2. Sheets
B9: Instructions - this page.
B10: Settings - company details, quarter dates, pro-rata %, VAT control accounts, GL column names for the import script. (Yellow cells = your input.)
B11: GL_Input - the full GL for the quarter. Columns A-L are inputs (paste or import). Columns M-Z are formulas - do not overwrite them.
B12: Account_Mapping - one row per GL account with its default VAT code. Carried forward from quarter to quarter.
B13: Counterparties - one row per customer/supplier: country (ISO code), VAT number and inter-company flag. Drives the EU / 3rd-country / inter-company split.
B14: VAT_Codes - the VAT treatments and which return boxes each one feeds. Totals per code are calculated here.
B15: FX_Rates / FX_Daily - daily ECB euro reference rates for the quarter and the quarterly average used in GL_Input.
B16: VAT_Return - the VAT 4 form with every box, the amount, what the box must include and which codes feed it.
... B59: The VAT codes and box mapping follow the Tax Department's VAT 4 guidance and Big Four / practitioner guides as at October 2026. VAT rules (rates, temporary zero rates, reverse-charge lists) change often - review VAT_Codes and Legal_Notes every quarter. This working is a preparation tool, not tax advice; complex items (property, construction, capital goods adjustments, partial exemption annual adjustments, VAT groups, fixed establishments) need specific review.

Sheet Settings
A1: Settings
A2: Yellow cells are inputs. Dates drive the period checks, VIES months and due date.
B4: Company name | C4: Example Holdings Ltd | D4: Legal name as registered with the Tax Department.
B5: VAT registration number | C5: 10000000X | D5: Cyprus VAT number (8 digits + letter).
B6: Tax Identification Code (TIC) | D6: Optional.
B7: Quarter | C7: Q3 2026 | D7: Label only.
B8: Period start | C8: 46204 | D8: First day of the VAT quarter.
B9: Period end | C9: 46295 | D9: Last day of the VAT quarter.
B10: Input VAT recovery % (pro-rata) for mixed-use costs | C10: 1 | D10: Provisional % = taxable (incl. outside-scope with right) supplies / total supplies of the previous year. 100% if no exempt supplies. Annual adjustment at year end.
B11: Reverse-charge VAT is booked in the GL VAT control accounts? (Y/N) | C11: N | D11: Y if your bookkeeping posts the self-assessed reverse-charge VAT to the output and input VAT accounts. Used by the Reconciliation sheet.
B12: Reconciliation tolerance (EUR) | C12: 5 | D12: Differences above this amount are flagged.
B13: Return and payment due date | C13: =DATE(YEAR(C9),MONTH(C9)+2,10) -> 46336 | D13: 10th day of the second month after the end of the quarter (next working day if a weekend / holiday).
B14: VIES statements due | C14: 15th of each following month | D14: Monthly recapitulative statement for EU supplies of goods and services (TFA portal).
B17: Output VAT control account codes (credit balances)
B18: Output VAT account 1 | C18: 2201
B19: Output VAT account 2
B20: Output VAT account 3
B21: Output VAT account 4
B22: Output VAT account 5
B25: Input VAT control account codes (debit balances) - excl. import VAT account
B26: Input VAT account 1 | C26: 2101
B27: Input VAT account 2
B28: Input VAT account 3
B29: Input VAT account 4
B30: Input VAT account 5
B33: GL column map (for the import-gl command) | D33: Type the header text exactly as it appears in your GL export. Leave blank if the column does not exist. Give either 'Amount' (Dr + / Cr -) or both 'Debit' and 'Credit'.
B34: Working field | C34: Header in your GL export | D34: Notes
B35: date | C35: Date | D35: Posting or document date.
B36: doc | C36: Doc No
B37: account | C37: Account | D37: Account code.
B38: account_name | C38: Account Name
B39: description | C39: Description
B40: cp_code | C40: Counterparty | D40: Customer / supplier code (or name) - the key to Counterparties.
B41: cp_name | C41: Counterparty Name
B42: currency | C42: Currency | D42: ISO currency code. Blank = EUR.
B43: amount_fc | C43: Amount | D43: Signed amount in transaction currency (Dr + / Cr -).
B44: debit_fc | D44: Use instead of 'Amount' when the export has separate debit and credit columns.
B45: credit_fc
B46: amount_eur | D46: Optional: amount already in EUR (Dr + / Cr -). Takes priority over the FX conversion.
B47: vat_code | D47: Optional: VAT/tax code from your accounting system, if it uses the same codes as VAT_Codes.
...

Sheet GL_Input
A1: GL_Input - full general ledger for the VAT quarter
A2: Columns A-L: paste/import your GL (Debit = +, Credit = -). Columns M-Z: formulas, do not overwrite. Filter column Z for exceptions.
A3: INPUT >>> | M3: CALCULATED >>>
A4: Date | B4: Journal / Doc no. | C4: Account code | D4: Account name | E4: Description | F4: Counterparty code | G4: Counterparty name | H4: Currency | I4: Amount in currency (Dr + / Cr -) | J4: Amount EUR if in GL (Dr + / Cr -) | K4: VAT code override (optional) | L4: VAT amount in currency (optional) | M4: Account VAT code | N4: VAT code used | O4: Country | P4: Region (CY/EU/3RD) | Q4: Inter-company (Y/N) | R4: FX rate (ccy per EUR) | S4: Amount EUR (Dr + / Cr -) | T4: Nature | U4: Return value EUR | V4: VAT rate | W4: VAT EUR | X4: VIES type | Y4: Month in quarter | Z4: Check
A5: 46208 | B5: SI-1001 | C5: 4000 | D5: Sales - Cyprus customers | E5: Consulting services July | F5: C-CY01 | G5: Limassol Trading Ltd | H5: EUR | I5: -10000 | M5: =IF($C5="","",IFERROR(INDEX(Account_Mapping!$C:$C,MATCH($C5&"",Account_Mapping!$A:$A,0))&"","")) -> S19 | N5: =IF($K5<>"",$K5,$M5) -> S19 | O5: =IF($F5="","",IFERROR(INDEX(Counterparties!$C:$C,MATCH($F5&"",Counterparties!$A:$A,0))&"","")) -> CY | P5: =IF($O5="","",IF($O5="CY","CY",IF(ISNUMBER(MATCH($O5,Lists!$A:$A,0)),"EU","3RD"))) -> CY | Q5: =IF($F5="","N",IFERROR(IF(INDEX(Counterparties!$E:$E,MATCH($F5&"",Counterparties!$A:$A,0))="Y","Y","N"),"N")) -> N | R5: =IF(OR($H5="",$H5="EUR"),1,IFERROR(INDEX(FX_Rates!$D:$D,MATCH($H5,FX_Rates!$A:$A,0)),"")) -> 1 | S5: =IF(AND($I5="",$J5=""),"",IF($J5<>"",$J5,IF(OR($R5="",$R5=0),"",ROUND($I5/$R5,2)))) -> -10000 | T5: =IF($N5="","",IFERROR(INDEX(VAT_Codes!$C:$C,MATCH($N5,VAT_Codes!$A:$A,0)),"")&"") -> Output | U5: =IF(OR($S5="",$T5="",$T5="None"),0,IF($T5="Output",-$S5,$S5)) -> 10000 | V5: =IF($N5="",0,IFERROR(INDEX(VAT_Codes!$D:$D,MATCH($N5,VAT_Codes!$A:$A,0)),0)) -> 0.19 | W5: =IF($U5=0,0,IF(IFERROR(INDEX(VAT_Codes!$F:$F,MATCH($N5,VAT_Codes!$A:$A,0)),"N")="Y",$U5,IF($L5<>"",ROUND(ABS($L5)/IF(OR($R5="",$R5=0),1,$R5),2)*SIGN($U5),ROUND($U5*$V5,2)))) -> 1900 | X5: =IF($N5="","",IFERROR(INDEX(VAT_Codes!$H:$H,MATCH($N5,VAT_Codes!$A:$A,0)),"")&"") | Y5: =IF($A5="","",(YEAR($A5)-YEAR(Settings!$C$8))*12+MONTH($A5)-MONTH(Settings!$C$8)+1) -> 1 | Z5: =IF(AND($C5="",$I5="",$J5=""),"",IF($N5="","NO VAT CODE",IF($T5="","UNKNOWN VAT CODE",IF($S5="","MISSING FX RATE",IF(OR($A5<Settings!$C$8,$A5>Settings!$C$9),"OUTSIDE PERIOD",IF(AND(IFERROR(INDEX(VAT_Codes!$E:$E,MATCH($N5,VAT_Codes!$A:$A,0)),"ANY")<>"ANY",$P5=""),"MISSING COUNTERPARTY COUNTRY",IF(AND(IFERROR(INDEX(VAT_Codes!$E:$E,MATCH($N5,VAT_Codes!$A:$A,0)),"ANY")<>"ANY",$P5<>IFERROR(INDEX(VAT_Codes!$E:$E,MATCH($N5,VAT_Codes!$A:$A,0)),"ANY")),"REGION MISMATCH","OK"))))))) -> OK
A6: 46208 | B6: SI-1001 | C6: 2201 | D6: Output VAT | E6: VAT on SI-1001 | F6: C-CY01 | G6: Limassol Trading Ltd | H6: EUR | I6: -1900 | M6: =IF($C6="","",IFERROR(INDEX(Account_Mapping!$C:$C,MATCH($C6&"",Account_Mapping!$A:$A,0))&"","")) -> NR | N6: =IF($K6<>"",$K6,$M6) -> NR | O6: =IF($F6="","",IFERROR(INDEX(Counterparties!$C:$C,MATCH($F6&"",Counterparties!$A:$A,0))&"","")) -> CY | P6: =IF($O6="","",IF($O6="CY","CY",IF(ISNUMBER(MATCH($O6,Lists!$A:$A,0)),"EU","3RD"))) -> CY | Q6: =IF($F6="","N",IFERROR(IF(INDEX(Counterparties!$E:$E,MATCH($F6&"",Counterparties!$A:$A,0))="Y","Y","N"),"N")) -> N | R6: =IF(OR($H6="",$H6="EUR"),1,IFERROR(INDEX(FX_Rates!$D:$D,MATCH($H6,FX_Rates!$A:$A,0)),"")) -> 1 | S6: =IF(AND($I6="",$J6=""),"",IF($J6<>"",$J6,IF(OR($R6="",$R6=0),"",ROUND($I6/$R6,2)))) -> -1900 | T6: =IF($N6="","",IFERROR(INDEX(VAT_Codes!$C:$C,MATCH($N6,VAT_Codes!$A:$A,0)),"")&"") -> None | U6: =IF(OR($S6="",$T6="",$T6="None"),0,IF($T6="Output",-$S6,$S6)) -> 0 | V6: =IF($N6="",0,IFERROR(INDEX(VAT_Codes!$D:$D,MATCH($N6,VAT_Codes!$A:$A,0)),0)) -> 0 | W6: =IF($U6=0,0,IF(IFERROR(INDEX(VAT_Codes!$F:$F,MATCH($N6,VAT_Codes!$A:$A,0)),"N")="Y",$U6,IF($L6<>"",ROUND(ABS($L6)/IF(OR($R6="",$R6=0),1,$R6),2)*SIGN($U6),ROUND($U6*$V6,2)))) -> 0 | X6: =IF($N6="","",IFERROR(INDEX(VAT_Codes!$H:$H,MATCH($N6,VAT_Codes!$A:$A,0)),"")&"") | Y6: =IF($A6="","",(YEAR($A6)-YEAR(Settings!$C$8))*12+MONTH($A6)-MONTH(Settings!$C$8)+1) -> 1 | Z6: =IF(AND($C6="",$I6="",$J6=""),"",IF($N6="","NO VAT CODE",IF($T6="","UNKNOWN VAT CODE",IF($S6="","MISSING FX RATE",IF(OR($A6<Settings!$C$8,$A6>Settings!$C$9),"OUTSIDE PERIOD",IF(AND(IFERROR(INDEX(VAT_Codes!$E:$E,MATCH($N6,VAT_Codes!$A:$A,0)),"ANY")<>"ANY",$P6=""),"MISSING COUNTERPARTY COUNTRY",IF(AND(IFERROR(INDEX(VAT_Codes!$E:$E,MATCH($N6,VAT_Codes!$A:$A,0)),"ANY")<>"ANY",$P6<>IFERROR(INDEX(VAT_Codes!$E:$E,MATCH($N6,VAT_Codes!$A:$A,0)),"ANY")),"REGION MISMATCH","OK"))))))) -> OK
A7: 46231 | B7: SI-1002 | C7: 4100 | D7: Management fees - group | E7: Q3 management fee | F7: IC-DE01 | G7: Example GmbH (group) | H7: EUR | I7: -25000 | M7: =IF($C7="","",IFERROR(INDEX(Account_Mapping!$C:$C,MATCH($C7&"",Account_Mapping!$A:$A,0))&"","")) -> EUS | N7: =IF($K7<>"",$K7,$M7) -> EUS | O7: =IF($F7="","",IFERROR(INDEX(Counterparties!$C:$C,MATCH($F7&"",Counterparties!$A:$A,0))&"","")) -> DE | P7: =IF($O7="","",IF($O7="CY","CY",IF(ISNUMBER(MATCH($O7,Lists!$A:$A,0)),"EU","3RD"))) -> EU | Q7: =IF($F7="","N",IFERROR(IF(INDEX(Counterparties!$E:$E,MATCH($F7&"",Counterparties!$A:$A,0))="Y","Y","N"),"N")) -> Y | R7: =IF(OR($H7="",$H7="EUR"),1,IFERROR(INDEX(FX_Rates!$D:$D,MATCH($H7,FX_Rates!$A:$A,0)),"")) -> 1 | S7: =IF(AND($I7="",$J7=""),"",IF($J7<>"",$J7,IF(OR($R7="",$R7=0),"",ROUND($I7/$R7,2)))) -> -25000 | T7: =IF($N7="","",IFERROR(INDEX(VAT_Codes!$C:$C,MATCH($N7,VAT_Codes!$A:$A,0)),"")&"") -> Output | U7: =IF(OR($S7="",$T7="",$T7="None"),0,IF($T7="Output",-$S7,$S7)) -> 25000 | V7: =IF($N7="",0,IFERROR(INDEX(VAT_Codes!$D:$D,MATCH($N7,VAT_Codes!$A:$A,0)),0)) -> 0 | W7: =IF($U7=0,0,IF(IFERROR(INDEX(VAT_Codes!$F:$F,MATCH($N7,VAT_Codes!$A:$A,0)),"N")="Y",$U7,IF($L7<>"",ROUND(ABS($L7)/IF(OR($R7="",$R7=0),1,$R7),2)*SIGN($U7),ROUND($U7*$V7,2)))) -> 0 | X7: =IF($N7="","",IFERROR(INDEX(VAT_Codes!$H:$H,MATCH($N7,VAT_Codes!$A:$A,0)),"")&"") -> S | Y7: =IF($A7="","",(YEAR($A7)-YEAR(Settings!$C$8))*12+MONTH($A7)-MONTH(Settings!$C$8)+1) -> 1 | Z7: =IF(AND($C7="",$I7="",$J7=""),"",IF($N7="","NO VAT CODE",IF($T7="","UNKNOWN VAT CODE",IF($S7="","MISSING FX RATE",IF(OR($A7<Settings!$C$8,$A7>Settings!$C$9),"OUTSIDE PERIOD",IF(AND(IFERROR(INDEX(VAT_Codes!$E:$E,MATCH($N7,VAT_Codes!$A:$A,0)),"ANY")<>"ANY",$P7=""),"MISSING COUNTERPARTY COUNTRY",IF(AND(IFERROR(INDEX(VAT_Codes!$E:$E,MATCH($N7,VAT_Codes!$A:$A,0)),"ANY")<>"ANY",$P7<>IFERROR(INDEX(VAT_Codes!$E:$E,MATCH($N7,VAT_Codes!$A:$A,0)),"ANY")),"REGION MISMATCH","OK"))))))) -> OK
A8: 46262 | B8: SI-1003 | C8: 4100 | D8: Management fees - group | E8: Q3 management fee | F8: IC-AE01 | G8: Example FZE Dubai (group) | H8: USD | I8: -30000 | K8: OS3 | M8: =IF($C8="","",IFERROR(INDEX(Account_Mapping!$C:$C,MATCH($C8&"",Account_Mapping!$A:$A,0))&"","")) -> EUS | N8: =IF($K8<>"",$K8,$M8) -> OS3 | O8: =IF($F8="","",IFERROR(INDEX(Counterparties!$C:$C,MATCH($F8&"",Counterparties!$A:$A,0))&"","")) -> AE | P8: =IF($O8="","",IF($O8="CY","CY",IF(ISNUMBER(MATCH($O8,Lists!$A:$A,0)),"EU","3RD"))) -> 3RD | Q8: =IF($F8="","N",IFERROR(IF(INDEX(Counterparties!$E:$E,MATCH($F8&"",Counterparties!$A:$A,0))="Y","Y","N"),"N")) -> Y | R8: =IF(OR($H8="",$H8="EUR"),1,IFERROR(INDEX(FX_Rates!$D:$D,MATCH($H8,FX_Rates!$A:$A,0)),"")) -> 1.1649 | S8: =IF(AND($I8="",$J8=""),"",IF($J8<>"",$J8,IF(OR($R8="",$R8=0),"",ROUND($I8/$R8,2)))) -> -25753.28 | T8: =IF($N8="","",IFERROR(INDEX(VAT_Codes!$C:$C,MATCH($N8,VAT_Codes!$A:$A,0)),"")&"") -> Output | U8: =IF(OR($S8="",$T8="",$T8="None"),0,IF($T8="Output",-$S8,$S8)) -> 25753.28 | V8: =IF($N8="",0,IFERROR(INDEX(VAT_Codes!$D:$D,MATCH($N8,VAT_Codes!$A:$A,0)),0)) -> 0 | W8: =IF($U8=0,0,IF(IFERROR(INDEX(VAT_Codes!$F:$F,MATCH($N8,VAT_Codes!$A:$A,0)),"N")="Y",$U8,IF($L8<>"",ROUND(ABS($L8)/IF(OR($R8="",$R8=0),1,$R8),2)*SIGN($U8),ROUND($U8*$V8,2)))) -> 0 | X8: =IF($N8="","",IFERROR(INDEX(VAT_Codes!$H:$H,MATCH($N8,VAT_Codes!$A:$A,0)),"")&"") | Y8: =IF($A8="","",(YEAR($A8)-YEAR(Settings!$C$8))*12+MONTH($A8)-MONTH(Settings!$C$8)+1) -> 2 | Z8: =IF(AND($C8="",$I8="",$J8=""),"",IF($N8="","NO VAT CODE",IF($T8="","UNKNOWN VAT CODE",IF($S8="","MISSING FX RATE",IF(OR($A8<Settings!$C$8,$A8>Settings!$C$9),"OUTSIDE PERIOD",IF(AND(IFERROR(INDEX(VAT_Codes!$E:$E,MATCH($N8,VAT_Codes!$A:$A,0)),"ANY")<>"ANY",$P8=""),"MISSING COUNTERPARTY COUNTRY",IF(AND(IFERROR(INDEX(VAT_Codes!$E:$E,MATCH($N8,VAT_Codes!$A:$A,0)),"ANY")<>"ANY",$P8<>IFERROR(INDEX(VAT_Codes!$E:$E,MATCH($N8,VAT_Codes!$A:$A,0)),"ANY")),"REGION MISMATCH","OK"))))))) -> OK
A9: 46246 | B9: SI-1004 | C9: 4300 | D9: Sales of goods - export / EU | E9: Goods to Italy | F9: C-IT01 | G9: Milano Srl | H9: EUR | I9: -8000 | M9: =IF($C9="","",IFERROR(INDEX(Account_Mapping!$C:$C,MATCH($C9&"",Account_Mapping!$A:$A,0))&"","")) -> EUG | N9: =IF($K9<>"",$K9,$M9) -> EUG | O9: =IF($F9="","",IFERROR(INDEX(Counterparties!$C:$C,MATCH($F9&"",Counterparties!$A:$A,0))&"","")) -> IT | P9: =IF($O9="","",IF($O9="CY","CY",IF(ISNUMBER(MATCH($O9,Lists!$A:$A,0)),"EU","3RD"))) -> EU | Q9: =IF($F9="","N",IFERROR(IF(INDEX(Counterparties!$E:$E,MATCH($F9&"",Counterparties!$A:$A,0))="Y","Y","N"),"N")) -> N | R9: =IF(OR($H9="",$H9="EUR"),1,IFERROR(INDEX(FX_Rates!$D:$D,MATCH($H9,FX_Rates!$A:$A,0)),"")) -> 1 | S9: =IF(AND($I9="",$J9=""),"",IF($J9<>"",$J9,IF(OR($R9="",$R9=0),"",ROUND($I9/$R9,2)))) -> -8000 | T9: =IF($N9="","",IFERROR(INDEX(VAT_Codes!$C:$C,MATCH($N9,VAT_Codes!$A:$A,0)),"")&"") -> Output | U9: =IF(OR($S9="",$T9="",$T9="None"),0,IF($T9="Output",-$S9,$S9)) -> 8000 | V9: =IF($N9="",0,IFERROR(INDEX(VAT_Codes!$D:$D,MATCH($N9,VAT_Codes!$A:$A,0)),0)) -> 0 | W9: =IF($U9=0,0,IF(IFERROR(INDEX(VAT_Codes!$F:$F,MATCH($N9,VAT_Codes!$A:$A,0)),"N")="Y",$U9,IF($L9<>"",ROUND(ABS($L9)/IF(OR($R9="",$R9=0),1,$R9),2)*SIGN($U9),ROUND($U9*$V9,2)))) -> 0 | X9: =IF($N9="","",IFERROR(INDEX(VAT_Codes!$H:$H,MATCH($N9,VAT_Codes!$A:$A,0)),"")&"") -> G | Y9: =IF($A9="","",(YEAR($A9)-YEAR(Settings!$C$8))*12+MONTH($A9)-MONTH(Settings!$C$8)+1) -> 2 | Z9: =IF(AND($C9="",$I9="",$J9=""),"",IF($N9="","NO VAT CODE",IF($T9="","UNKNOWN VAT CODE",IF($S9="","MISSING FX RATE",IF(OR($A9<Settings!$C$8,$A9>Settings!$C$9),"OUTSIDE PERIOD",IF(AND(IFERROR(INDEX(VAT_Codes!$E:$E,MATCH($N9,VAT_Codes!$A:$A,0)),"ANY")<>"ANY",$P9=""),"MISSING COUNTERPARTY COUNTRY",IF(AND(IFERROR(INDEX(VAT_Codes!$E:$E,MATCH($N9,VAT_Codes!$A:$A,0)),"ANY")<>"ANY",$P9<>IFERROR(INDEX(VAT_Codes!$E:$E,MATCH($N9,VAT_Codes!$A:$A,0)),"ANY")),"REGION MISMATCH","OK"))))))) -> OK
A10: 46268 | B10: SI-1005 | C10: 4300 | D10: Sales of goods - export / EU | E10: Goods to USA | F10: C-US01 | G10: Boston Inc | H10: USD | I10: -12000 | K10: EXPG | M10: =IF($C10="","",IFERROR(INDEX(Account_Mapping!$C:$C,MATCH($C10&"",Account_Mapping!$A:$A,0))&"","")) -> EUG | N10: =IF($K10<>"",$K10,$M10) -> EXPG | O10: =IF($F10="","",IFERROR(INDEX(Counterparties!$C:$C,MATCH($F10&"",Counterparties!$A:$A,0))&"","")) -> US | P10: =IF($O10="","",IF($O10="CY","CY",IF(ISNUMBER(MATCH($O10,Lists!$A:$A,0)),"EU","3RD"))) -> 3RD | Q10: =IF($F10="","N",IFERROR(IF(INDEX(Counterparties!$E:$E,MATCH($F10&"",Counterparties!$A:$A,0))="Y","Y","N"),"N")) -> N | R10: =IF(OR($H10="",$H10="EUR"),1,IFERROR(INDEX(FX_Rates!$D:$D,MATCH($H10,FX_Rates!$A:$A,0)),"")) -> 1.1649 | S10: =IF(AND($I10="",$J10=""),"",IF($J10<>"",$J10,IF(OR($R10="",$R10=0),"",ROUND($I10/$R10,2)))) -> -10301.31 | T10: =IF($N10="","",IFERROR(INDEX(VAT_Codes!$C:$C,MATCH($N10,VAT_Codes!$A:$A,0)),"")&"") -> Output | U10: =IF(OR($S10="",$T10="",$T10="None"),0,IF($T10="Output",-$S10,$S10)) -> 10301.31 | V10: =IF($N10="",0,IFERROR(INDEX(VAT_Codes!$D:$D,MATCH($N10,VAT_Codes!$A:$A,0)),0)) -> 0 | W10: =IF($U10=0,0,IF(IFERROR(INDEX(VAT_Codes!$F:$F,MATCH($N10,VAT_Codes!$A:$A,0)),"N")="Y",$U10,IF($L10<>"",ROUND(ABS($L10)/IF(OR($R10="",$R10=0),1,$R10),2)*SIGN($U10),ROUND($U10*$V10,2)))) -> 0 | X10: =IF($N10="","",IFERROR(INDEX(VAT_Codes!$H:$H,MATCH($N10,VAT_Codes!$A:$A,0)),"")&"") | Y10: =IF($A10="","",(YEAR($A10)-YEAR(Settings!$C$8))*12+MONTH($A10)-MONTH(Settings!$C$8)+1) -> 3 | Z10: =IF(AND($C10="",$I10="",$J10=""),"",IF($N10="","NO VAT CODE",IF($T10="","UNKNOWN VAT CODE",IF($S10="","MISSING FX RATE",IF(OR($A10<Settings!$C$8,$A10>Settings!$C$9),"OUTSIDE PERIOD",IF(AND(IFERROR(INDEX(VAT_Codes!$E:$E,MATCH($N10,VAT_Codes!$A:$A,0)),"ANY")<>"ANY",$P10=""),"MISSING COUNTERPARTY COUNTRY",IF(AND(IFERROR(INDEX(VAT_Codes!$E:$E,MATCH($N10,VAT_Codes!$A:$A,0)),"ANY")<>"ANY",$P10<>IFERROR(INDEX(VAT_Codes!$E:$E,MATCH($N10,VAT_Codes!$A:$A,0)),"ANY")),"REGION MISMATCH","OK"))))))) -> OK
A11: 46213 | B11: PI-501 | C11: 6000 | D11: Professional fees | E11: Audit fee | F11: S-CY01 | G11: Nicosia Audit Ltd | H11: EUR | I11: 2000 | M11: =IF($C11="","",IFERROR(INDEX(Account_Mapping!$C:$C,MATCH($C11&"",Account_Mapping!$A:$A,0))&"","")) -> P19 | N11: =IF($K11<>"",$K11,$M11) -> P19 | O11: =IF($F11="","",IFERROR(INDEX(Counterparties!$C:$C,MATCH($F11&"",Counterparties!$A:$A,0))&"","")) -> CY | P11: =IF($O11="","",IF($O11="CY","CY",IF(ISNUMBER(MATCH($O11,Lists!$A:$A,0)),"EU","3RD"))) -> CY | Q11: =IF($F11="","N",IFERROR(IF(INDEX(Counterparties!$E:$E,MATCH($F11&"",Counterparties!$A:$A,0))="Y","Y","N"),"N")) -> N | R11: =IF(OR($H11="",$H11="EUR"),1,IFERROR(INDEX(FX_Rates!$D:$D,MATCH($H11,FX_Rates!$A:$A,0)),"")) -> 1 | S11: =IF(AND($I11="",$J11=""),"",IF($J11<>"",$J11,IF(OR($R11="",$R11=0),"",ROUND($I11/$R11,2)))) -> 2000 | T11: =IF($N11="","",IFERROR(INDEX(VAT_Codes!$C:$C,MATCH($N11,VAT_Codes!$A:$A,0)),"")&"") -> Input | U11: =IF(OR($S11="",$T11="",$T11="None"),0,IF($T11="Output",-$S11,$S11)) -> 2000 | V11: =IF($N11="",0,IFERROR(INDEX(VAT_Codes!$D:$D,MATCH($N11,VAT_Codes!$A:$A,0)),0)) -> 0.19 | W11: =IF($U11=0,0,IF(IFERROR(INDEX(VAT_Codes!$F:$F,MATCH($N11,VAT_Codes!$A:$A,0)),"N")="Y",$U11,IF($L11<>"",ROUND(ABS($L11)/IF(OR($R11="",$R11=0),1,$R11),2)*SIGN($U11),ROUND($U11*$V11,2)))) -> 380 | X11: =IF($N11="","",IFERROR(INDEX(VAT_Codes!$H:$H,MATCH($N11,VAT_Codes!$A:$A,0)),"")&"") | Y11: =IF($A11="","",(YEAR($A11)-YEAR(Settings!$C$8))*12+MONTH($A11)-MONTH(Settings!$C$8)+1) -> 1 | Z11: =IF(AND($C11="",$I11="",$J11=""),"",IF($N11="","NO VAT CODE",IF($T11="","UNKNOWN VAT CODE",IF($S11="","MISSING FX RATE",IF(OR($A11<Settings!$C$8,$A11>Settings!$C$9),"OUTSIDE PERIOD",IF(AND(IFERROR(INDEX(VAT_Codes!$E:$E,MATCH($N11,VAT_Codes!$A:$A,0)),"ANY")<>"ANY",$P11=""),"MISSING COUNTERPARTY COUNTRY",IF(AND(IFERROR(INDEX(VAT_Codes!$E:$E,MATCH($N11,VAT_Codes!$A:$A,0)),"ANY")<>"ANY",$P11<>IFERROR(INDEX(VAT_Codes!$E:$E,MATCH($N11,VAT_Codes!$A:$A,0)),"ANY")),"REGION MISMATCH","OK"))))))) -> OK
A12: 46213 | B12: PI-501 | C12: 2101 | D12: Input VAT | E12: VAT on PI-501 | F12: S-CY01 | G12: Nicosia Audit Ltd | H12: EUR | I12: 380 | M12: =IF($C12="","",IFERROR(INDEX(Account_Mapping!$C:$C,MATCH($C12&"",Account_Mapping!$A:$A,0))&"","")) -> NR | N12: =IF($K12<>"",$K12,$M12) -> NR | O12: =IF($F12="","",IFERROR(INDEX(Counterparties!$C:$C,MATCH($F12&"",Counterparties!$A:$A,0))&"","")) -> CY | P12: =IF($O12="","",IF($O12="CY","CY",IF(ISNUMBER(MATCH($O12,Lists!$A:$A,0)),"EU","3RD"))) -> CY | Q12: =IF($F12="","N",IFERROR(IF(INDEX(Counterparties!$E:$E,MATCH($F12&"",Counterparties!$A:$A,0))="Y","Y","N"),"N")) -> N | R12: =IF(OR($H12="",$H12="EUR"),1,IFERROR(INDEX(FX_Rates!$D:$D,MATCH($H12,FX_Rates!$A:$A,0)),"")) -> 1 | S12: =IF(AND($I12="",$J12=""),"",IF($J12<>"",$J12,IF(OR($R12="",$R12=0),"",ROUND($I12/$R12,2)))) -> 380 | T12: =IF($N12="","",IFERROR(INDEX(VAT_Codes!$C:$C,MATCH($N12,VAT_Codes!$A:$A,0)),"")&"") -> None | U12: =IF(OR($S12="",$T12="",$T12="None"),0,IF($T12="Output",-$S12,$S12)) -> 0 | V12: =IF($N12="",0,IFERROR(INDEX(VAT_Codes!$D:$D,MATCH($N12,VAT_Codes!$A:$A,0)),0)) -> 0 | W12: =IF($U12=0,0,IF(IFERROR(INDEX(VAT_Codes!$F:$F,MATCH($N12,VAT_Codes!$A:$A,0)),"N")="Y",$U12,IF($L12<>"",ROUND(ABS($L12)/IF(OR($R12="",$R12=0),1,$R12),2)*SIGN($U12),ROUND($U12*$V12,2)))) -> 0 | X12: =IF($N12="","",IFERROR(INDEX(VAT_Codes!$H:$H,MATCH($N12,VAT_Codes!$A:$A,0)),"")&"") | Y12: =IF($A12="","",(YEAR($A12)-YEAR(Settings!$C$8))*12+MONTH($A12)-MONTH(Settings!$C$8)+1) -> 1 | Z12: =IF(AND($C12="",$I12="",$J12=""),"",IF($N12="","NO VAT CODE",IF($T12="","UNKNOWN VAT CODE",IF($S12="","MISSING FX RATE",IF(OR($A12<Settings!$C$8,$A12>Settings!$C$9),"OUTSIDE PERIOD",IF(AND(IFERROR(INDEX(VAT_Codes!$E:$E,MATCH($N12,VAT_Codes!$A:$A,0)),"ANY")<>"ANY",$P12=""),"MISSING COUNTERPARTY COUNTRY",IF(AND(IFERROR(INDEX(VAT_Codes!$E:$E,MATCH($N12,VAT_Codes!$A:$A,0)),"ANY")<>"ANY",$P12<>IFERROR(INDEX(VAT_Codes!$E:$E,MATCH($N12,VAT_Codes!$A:$A,0)),"ANY")),"REGION MISMATCH","OK"))))))) -> OK
A13: 46254 | B13: PI-502 | C13: 6100 | D13: Group recharges | E13: IT recharge from parent | F13: IC-NL01 | G13: Example BV (parent) | H13: EUR | I13: 15000 | M13: =IF($C13="","",IFERROR(INDEX(Account_Mapping!$C:$C,MATCH($C13&"",Account_Mapping!$A:$A,0))&"","")) -> AES19 | N13: =IF($K13<>"",$K13,$M13) -> AES19 | O13: =IF($F13="","",IFERROR(INDEX(Counterparties!$C:$C,MATCH($F13&"",Counterparties!$A:$A,0))&"","")) -> NL | P13: =IF($O13="","",IF($O13="CY","CY",IF(ISNUMBER(MATCH($O13,Lists!$A:$A,0)),"EU","3RD"))) -> EU | Q13: =IF($F13="","N",IFERROR(IF(INDEX(Counterparties!$E:$E,MATCH($F13&"",Counterparties!$A:$A,0))="Y","Y","N"),"N")) -> Y | R13: =IF(OR($H13="",$H13="EUR"),1,IFERROR(INDEX(FX_Rates!$D:$D,MATCH($H13,FX_Rates!$A:$A,0)),"")) -> 1 | S13: =IF(AND($I13="",$J13=""),"",IF($J13<>"",$J13,IF(OR($R13="",$R13=0),"",ROUND($I13/$R13,2)))) -> 15000 | T13: =IF($N13="","",IFERROR(INDEX(VAT_Codes!$C:$C,MATCH($N13,VAT_Codes!$A:$A,0)),"")&"") -> Input | U13: =IF(OR($S13="",$T13="",$T13="None"),0,IF($T13="Output",-$S13,$S13)) -> 15000 | V13: =IF($N13="",0,IFERROR(INDEX(VAT_Codes!$D:$D,MATCH($N13,VAT_Codes!$A:$A,0)),0)) -> 0.19 | W13: =IF($U13=0,0,IF(IFERROR(INDEX(VAT_Codes!$F:$F,MATCH($N13,VAT_Codes!$A:$A,0)),"N")="Y",$U13,IF($L13<>"",ROUND(ABS($L13)/IF(OR($R13="",$R13=0),1,$R13),2)*SIGN($U13),ROUND($U13*$V13,2)))) -> 2850 | X13: =IF($N13="","",IFERROR(INDEX(VAT_Codes!$H:$H,MATCH($N13,VAT_Codes!$A:$A,0)),"")&"") | Y13: =IF($A13="","",(YEAR($A13)-YEAR(Settings!$C$8))*12+MONTH($A13)-MONTH(Settings!$C$8)+1) -> 2 | Z13: =IF(AND($C13="",$I13="",$J13=""),"",IF($N13="","NO VAT CODE",IF($T13="","UNKNOWN VAT CODE",IF($S13="","MISSING FX RATE",IF(OR($A13<Settings!$C$8,$A13>Settings!$C$9),"OUTSIDE PERIOD",IF(AND(IFERROR(INDEX(VAT_Codes!$E:$E,MATCH($N13,VAT_Codes!$A:$A,0)),"ANY")<>"ANY",$P13=""),"MISSING COUNTERPARTY COUNTRY",IF(AND(IFERROR(INDEX(VAT_Codes!$E:$E,MATCH($N13,VAT_Codes!$A:$A,0)),"ANY")<>"ANY",$P13<>IFERROR(INDEX(VAT_Codes!$E:$E,MATCH($N13,VAT_Codes!$A:$A,0)),"ANY")),"REGION MISMATCH","OK"))))))) -> OK
A14: 46236 | B14: PI-503 | C14: 6000 | D14: Professional fees | E14: Software subscription | F14: S-US01 | G14: Cloudsoft Inc | H14: USD | I14: 1200 | K14: A3S19 | M14: =IF($C14="","",IFERROR(INDEX(Account_Mapping!$C:$C,MATCH($C14&"",Account_Mapping!$A:$A,0))&"","")) -> P19 | N14: =IF($K14<>"",$K14,$M14) -> A3S19 | O14: =IF($F14="","",IFERROR(INDEX(Counterparties!$C:$C,MATCH($F14&"",Counterparties!$A:$A,0))&"","")) -> US | P14: =IF($O14="","",IF($O14="CY","CY",IF(ISNUMBER(MATCH($O14,Lists!$A:$A,0)),"EU","3RD"))) -> 3RD | Q14: =IF($F14="","N",IFERROR(IF(INDEX(Counterparties!$E:$E,MATCH($F14&"",Counterparties!$A:$A,0))="Y","Y","N"),"N")) -> N | R14: =IF(OR($H14="",$H14="EUR"),1,IFERROR(INDEX(FX_Rates!$D:$D,MATCH($H14,FX_Rates!$A:$A,0)),"")) -> 1.1649 | S14: =IF(AND($I14="",$J14=""),"",IF($J14<>"",$J14,IF(OR($R14="",$R14=0),"",ROUND($I14/$R14,2)))) -> 1030.13 | T14: =IF($N14="","",IFERROR(INDEX(VAT_Codes!$C:$C,MATCH($N14,VAT_Codes!$A:$A,0)),"")&"") -> Input | U14: =IF(OR($S14="",$T14="",$T14="None"),0,IF($T14="Output",-$S14,$S14)) -> 1030.13 | V14: =IF($N14="",0,IFERROR(INDEX(VAT_Codes!$D:$D,MATCH($N14,VAT_Codes!$A:$A,0)),0)) -> 0.19 | W14: =IF($U14=0,0,IF(IFERROR(INDEX(VAT_Codes!$F:$F,MATCH($N14,VAT_Codes!$A:$A,0)),"N")="Y",$U14,IF($L14<>"",ROUND(ABS($L14)/IF(OR($R14="",$R14=0),1,$R14),2)*SIGN($U14),ROUND($U14*$V14,2)))) -> 195.72 | X14: =IF($N14="","",IFERROR(INDEX(VAT_Codes!$H:$H,MATCH($N14,VAT_Codes!$A:$A,0)),"")&"") | Y14: =IF($A14="","",(YEAR($A14)-YEAR(Settings!$C$8))*12+MONTH($A14)-MONTH(Settings!$C$8)+1) -> 2 | Z14: =IF(AND($C14="",$I14="",$J14=""),"",IF($N14="","NO VAT CODE",IF($T14="","UNKNOWN VAT CODE",IF($S14="","MISSING FX RATE",IF(OR($A14<Settings!$C$8,$A14>Settings!$C$9),"OUTSIDE PERIOD",IF(AND(IFERROR(INDEX(VAT_Codes!$E:$E,MATCH($N14,VAT_Codes!$A:$A,0)),"ANY")<>"ANY",$P14=""),"MISSING COUNTERPARTY COUNTRY",IF(AND(IFERROR(INDEX(VAT_Codes!$E:$E,MATCH($N14,VAT_Codes!$A:$A,0)),"ANY")<>"ANY",$P14<>IFERROR(INDEX(VAT_Codes!$E:$E,MATCH($N14,VAT_Codes!$A:$A,0)),"ANY")),"REGION MISMATCH","OK"))))))) -> OK
A15: 46273 | B15: PI-504 | C15: 5000 | D15: Purchases of goods | E15: Goods from Germany | F15: S-DE01 | G15: Hamburg Supplies GmbH | H15: EUR | I15: 5000 | M15: =IF($C15="","",IFERROR(INDEX(Account_Mapping!$C:$C,MATCH($C15&"",Account_Mapping!$A:$A,0))&"","")) -> AEG19 | N15: =IF($K15<>"",$K15,$M15) -> AEG19 | O15: =IF($F15="","",IFERROR(INDEX(Counterparties!$C:$C,MATCH($F15&"",Counterparties!$A:$A,0))&"","")) -> DE | P15: =IF($O15="","",IF($O15="CY","CY",IF(ISNUMBER(MATCH($O15,Lists!$A:$A,0)),"EU","3RD"))) -> EU | Q15: =IF($F15="","N",IFERROR(IF(INDEX(Counterparties!$E:$E,MATCH($F15&"",Counterparties!$A:$A,0))="Y","Y","N"),"N")) -> N | R15: =IF(OR($H15="",$H15="EUR"),1,IFERROR(INDEX(FX_Rates!$D:$D,MATCH($H15,FX_Rates!$A:$A,0)),"")) -> 1 | S15: =IF(AND($I15="",$J15=""),"",IF($J15<>"",$J15,IF(OR($R15="",$R15=0),"",ROUND($I15/$R15,2)))) -> 5000 | T15: =IF($N15="","",IFERROR(INDEX(VAT_Codes!$C:$C,MATCH($N15,VAT_Codes!$A:$A,0)),"")&"") -> Input | U15: =IF(OR($S15="",$T15="",$T15="None"),0,IF($T15="Output",-$S15,$S15)) -> 5000 | V15: =IF($N15="",0,IFERROR(INDEX(VAT_Codes!$D:$D,MATCH($N15,VAT_Codes!$A:$A,0)),0)) -> 0.19 | W15: =IF($U15=0,0,IF(IFERROR(INDEX(VAT_Codes!$F:$F,MATCH($N15,VAT_Codes!$A:$A,0)),"N")="Y",$U15,IF($L15<>"",ROUND(ABS($L15)/IF(OR($R15="",$R15=0),1,$R15),2)*SIGN($U15),ROUND($U15*$V15,2)))) -> 950 | X15: =IF($N15="","",IFERROR(INDEX(VAT_Codes!$H:$H,MATCH($N15,VAT_Codes!$A:$A,0)),"")&"") | Y15: =IF($A15="","",(YEAR($A15)-YEAR(Settings!$C$8))*12+MONTH($A15)-MONTH(Settings!$C$8)+1) -> 3 | Z15: =IF(AND($C15="",$I15="",$J15=""),"",IF($N15="","NO VAT CODE",IF($T15="","UNKNOWN VAT CODE",IF($S15="","MISSING FX RATE",IF(OR($A15<Settings!$C$8,$A15>Settings!$C$9),"OUTSIDE PERIOD",IF(AND(IFERROR(INDEX(VAT_Codes!$E:$E,MATCH($N15,VAT_Codes!$A:$A,0)),"ANY")<>"ANY",$P15=""),"MISSING COUNTERPARTY COUNTRY",IF(AND(IFERROR(INDEX(VAT_Codes!$E:$E,MATCH($N15,VAT_Codes!$A:$A,0)),"ANY")<>"ANY",$P15<>IFERROR(INDEX(VAT_Codes!$E:$E,MATCH($N15,VAT_Codes!$A:$A,0)),"ANY")),"REGION MISMATCH","OK"))))))) -> OK
A16: 46280 | B16: PI-505 | C16: 5010 | D16: Imports of goods | E16: Goods from China | F16: S-CN01 | G16: Shenzhen Mfg Co | H16: USD | I16: 4000 | M16: =IF($C16="","",IFERROR(INDEX(Account_Mapping!$C:$C,MATCH($C16&"",Account_Mapping!$A:$A,0))&"","")) -> IMP | N16: =IF($K16<>"",$K16,$M16) -> IMP | O16: =IF($F16="","",IFERROR(INDEX(Counterparties!$C:$C,MATCH($F16&"",Counterparties!$A:$A,0))&"","")) -> CN | P16: =IF($O16="","",IF($O16="CY","CY",IF(ISNUMBER(MATCH($O16,Lists!$A:$A,0)),"EU","3RD"))) -> 3RD | Q16: =IF($F16="","N",IFERROR(IF(INDEX(Counterparties!$E:$E,MATCH($F16&"",Counterparties!$A:$A,0))="Y","Y","N"),"N")) -> N | R16: =IF(OR($H16="",$H16="EUR"),1,IFERROR(INDEX(FX_Rates!$D:$D,MATCH($H16,FX_Rates!$A:$A,0)),"")) -> 1.1649 | S16: =IF(AND($I16="",$J16=""),"",IF($J16<>"",$J16,IF(OR($R16="",$R16=0),"",ROUND($I16/$R16,2)))) -> 3433.77 | T16: =IF($N16="","",IFERROR(INDEX(VAT_Codes!$C:$C,MATCH($N16,VAT_Codes!$A:$A,0)),"")&"") -> Input | U16: =IF(OR($S16="",$T16="",$T16="None"),0,IF($T16="Output",-$S16,$S16)) -> 3433.77 | V16: =IF($N16="",0,IFERROR(INDEX(VAT_Codes!$D:$D,MATCH($N16,VAT_Codes!$A:$A,0)),0)) -> 0 | W16: =IF($U16=0,0,IF(IFERROR(INDEX(VAT_Codes!$F:$F,MATCH($N16,VAT_Codes!$A:$A,0)),"N")="Y",$U16,IF($L16<>"",ROUND(ABS($L16)/IF(OR($R16="",$R16=0),1,$R16),2)*SIGN($U16),ROUND($U16*$V16,2)))) -> 0 | X16: =IF($N16="","",IFERROR(INDEX(VAT_Codes!$H:$H,MATCH($N16,VAT_Codes!$A:$A,0)),"")&"") | Y16: =IF($A16="","",(YEAR($A16)-YEAR(Settings!$C$8))*12+MONTH($A16)-MONTH(Settings!$C$8)+1) -> 3 | Z16: =IF(AND($C16="",$I16="",$J16=""),"",IF($N16="","NO VAT CODE",IF($T16="","UNKNOWN VAT CODE",IF($S16="","MISSING FX RATE",IF(OR($A16<Settings!$C$8,$A16>Settings!$C$9),"OUTSIDE PERIOD",IF(AND(IFERROR(INDEX(VAT_Codes!$E:$E,MATCH($N16,VAT_Codes!$A:$A,0)),"ANY")<>"ANY",$P16=""),"MISSING COUNTERPARTY COUNTRY",IF(AND(IFERROR(INDEX(VAT_Codes!$E:$E,MATCH($N16,VAT_Codes!$A:$A,0)),"ANY")<>"ANY",$P16<>IFERROR(INDEX(VAT_Codes!$E:$E,MATCH($N16,VAT_Codes!$A:$A,0)),"ANY")),"REGION MISMATCH","OK"))))))) -> OK
A17: 46280 | B17: C-77 | C17: 2105 | D17: Import VAT paid to Customs | E17: Import VAT SAD 26CY... | H17: EUR | I17: 700 | M17: =IF($C17="","",IFERROR(INDEX(Account_Mapping!$C:$C,MATCH($C17&"",Account_Mapping!$A:$A,0))&"","")) -> IVAT | N17: =IF($K17<>"",$K17,$M17) -> IVAT | O17: =IF($F17="","",IFERROR(INDEX(Counterparties!$C:$C,MATCH($F17&"",Counterparties!$A:$A,0))&"","")) | P17: =IF($O17="","",IF($O17="CY","CY",IF(ISNUMBER(MATCH($O17,Lists!$A:$A,0)),"EU","3RD"))) | Q17: =IF($F17="","N",IFERROR(IF(INDEX(Counterparties!$E:$E,MATCH($F17&"",Counterparties!$A:$A,0))="Y","Y","N"),"N")) -> N | R17: =IF(OR($H17="",$H17="EUR"),1,IFERROR(INDEX(FX_Rates!$D:$D,MATCH($H17,FX_Rates!$A:$A,0)),"")) -> 1 | S17: =IF(AND($I17="",$J17=""),"",IF($J17<>"",$J17,IF(OR($R17="",$R17=0),"",ROUND($I17/$R17,2)))) -> 700 | T17: =IF($N17="","",IFERROR(INDEX(VAT_Codes!$C:$C,MATCH($N17,VAT_Codes!$A:$A,0)),"")&"") -> Input | U17: =IF(OR($S17="",$T17="",$T17="None"),0,IF($T17="Output",-$S17,$S17)) -> 700 | V17: =IF($N17="",0,IFERROR(INDEX(VAT_Codes!$D:$D,MATCH($N17,VAT_Codes!$A:$A,0)),0)) -> 0 | W17: =IF($U17=0,0,IF(IFERROR(INDEX(VAT_Codes!$F:$F,MATCH($N17,VAT_Codes!$A:$A,0)),"N")="Y",$U17,IF($L17<>"",ROUND(ABS($L17)/IF(OR($R17="",$R17=0),1,$R17),2)*SIGN($U17),ROUND($U17*$V17,2)))) -> 700 | X17: =IF($N17="","",IFERROR(INDEX(VAT_Codes!$H:$H,MATCH($N17,VAT_Codes!$A:$A,0)),"")&"") | Y17: =IF($A17="","",(YEAR($A17)-YEAR(Settings!$C$8))*12+MONTH($A17)-MONTH(Settings!$C$8)+1) -> 3 | Z17: =IF(AND($C17="",$I17="",$J17=""),"",IF($N17="","NO VAT CODE",IF($T17="","UNKNOWN VAT CODE",IF($S17="","MISSING FX RATE",IF(OR($A17<Settings!$C$8,$A17>Settings!$C$9),"OUTSIDE PERIOD",IF(AND(IFERROR(INDEX(VAT_Codes!$E:$E,MATCH($N17,VAT_Codes!$A:$A,0)),"ANY")<>"ANY",$P17=""),"MISSING COUNTERPARTY COUNTRY",IF(AND(IFERROR(INDEX(VAT_Codes!$E:$E,MATCH($N17,VAT_Codes!$A:$A,0)),"ANY")<>"ANY",$P17<>IFERROR(INDEX(VAT_Codes!$E:$E,MATCH($N17,VAT_Codes!$A:$A,0)),"ANY")),"REGION MISMATCH","OK"))))))) -> OK
A18: 46259 | B18: PI-506 | C18: 6500 | D18: Entertainment | E18: Client dinner | F18: S-CY02 | G18: Paphos Restaurant Ltd | H18: EUR | I18: 300 | L18: 57 | M18: =IF($C18="","",IFERROR(INDEX(Account_Mapping!$C:$C,MATCH($C18&"",Account_Mapping!$A:$A,0))&"","")) -> PB19 | N18: =IF($K18<>"",$K18,$M18) -> PB19 | O18: =IF($F18="","",IFERROR(INDEX(Counterparties!$C:$C,MATCH($F18&"",Counterparties!$A:$A,0))&"","")) -> CY | P18: =IF($O18="","",IF($O18="CY","CY",IF(ISNUMBER(MATCH($O18,Lists!$A:$A,0)),"EU","3RD"))) -> CY | Q18: =IF($F18="","N",IFERROR(IF(INDEX(Counterparties!$E:$E,MATCH($F18&"",Counterparties!$A:$A,0))="Y","Y","N"),"N")) -> N | R18: =IF(OR($H18="",$H18="EUR"),1,IFERROR(INDEX(FX_Rates!$D:$D,MATCH($H18,FX_Rates!$A:$A,0)),"")) -> 1 | S18: =IF(AND($I18="",$J18=""),"",IF($J18<>"",$J18,IF(OR($R18="",$R18=0),"",ROUND($I18/$R18,2)))) -> 300 | T18: =IF($N18="","",IFERROR(INDEX(VAT_Codes!$C:$C,MATCH($N18,VAT_Codes!$A:$A,0)),"")&"") -> Input | U18: =IF(OR($S18="",$T18="",$T18="None"),0,IF($T18="Output",-$S18,$S18)) -> 300 | V18: =IF($N18="",0,IFERROR(INDEX(VAT_Codes!$D:$D,MATCH($N18,VAT_Codes!$A:$A,0)),0)) -> 0.19 | W18: =IF($U18=0,0,IF(IFERROR(INDEX(VAT_Codes!$F:$F,MATCH($N18,VAT_Codes!$A:$A,0)),"N")="Y",$U18,IF($L18<>"",ROUND(ABS($L18)/IF(OR($R18="",$R18=0),1,$R18),2)*SIGN($U18),ROUND($U18*$V18,2)))) -> 57 | X18: =IF($N18="","",IFERROR(INDEX(VAT_Codes!$H:$H,MATCH($N18,VAT_Codes!$A:$A,0)),"")&"") | Y18: =IF($A18="","",(YEAR($A18)-YEAR(Settings!$C$8))*12+MONTH($A18)-MONTH(Settings!$C$8)+1) -> 2 | Z18: =IF(AND($C18="",$I18="",$J18=""),"",IF($N18="","NO VAT CODE",IF($T18="","UNKNOWN VAT CODE",IF($S18="","MISSING FX RATE",IF(OR($A18<Settings!$C$8,$A18>Settings!$C$9),"OUTSIDE PERIOD",IF(AND(IFERROR(INDEX(VAT_Codes!$E:$E,MATCH($N18,VAT_Codes!$A:$A,0)),"ANY")<>"ANY",$P18=""),"MISSING COUNTERPARTY COUNTRY",IF(AND(IFERROR(INDEX(VAT_Codes!$E:$E,MATCH($N18,VAT_Codes!$A:$A,0)),"ANY")<>"ANY",$P18<>IFERROR(INDEX(VAT_Codes!$E:$E,MATCH($N18,VAT_Codes!$A:$A,0)),"ANY")),"REGION MISMATCH","OK"))))))) -> OK
A19: 46231 | B19: PAY-07 | C19: 7000 | D19: Salaries | E19: July payroll | H19: EUR | I19: 20000 | M19: =IF($C19="","",IFERROR(INDEX(Account_Mapping!$C:$C,MATCH($C19&"",Account_Mapping!$A:$A,0))&"","")) -> NR | N19: =IF($K19<>"",$K19,$M19) -> NR | O19: =IF($F19="","",IFERROR(INDEX(Counterparties!$C:$C,MATCH($F19&"",Counterparties!$A:$A,0))&"","")) | P19: =IF($O19="","",IF($O19="CY","CY",IF(ISNUMBER(MATCH($O19,Lists!$A:$A,0)),"EU","3RD"))) | Q19: =IF($F19="","N",IFERROR(IF(INDEX(Counterparties!$E:$E,MATCH($F19&"",Counterparties!$A:$A,0))="Y","Y","N"),"N")) -> N | R19: =IF(OR($H19="",$H19="EUR"),1,IFERROR(INDEX(FX_Rates!$D:$D,MATCH($H19,FX_Rates!$A:$A,0)),"")) -> 1 | S19: =IF(AND($I19="",$J19=""),"",IF($J19<>"",$J19,IF(OR($R19="",$R19=0),"",ROUND($I19/$R19,2)))) -> 20000 | T19: =IF($N19="","",IFERROR(INDEX(VAT_Codes!$C:$C,MATCH($N19,VAT_Codes!$A:$A,0)),"")&"") -> None | U19: =IF(OR($S19="",$T19="",$T19="None"),0,IF($T19="Output",-$S19,$S19)) -> 0 | V19: =IF($N19="",0,IFERROR(INDEX(VAT_Codes!$D:$D,MATCH($N19,VAT_Codes!$A:$A,0)),0)) -> 0 | W19: =IF($U19=0,0,IF(IFERROR(INDEX(VAT_Codes!$F:$F,MATCH($N19,VAT_Codes!$A:$A,0)),"N")="Y",$U19,IF($L19<>"",ROUND(ABS($L19)/IF(OR($R19="",$R19=0),1,$R19),2)*SIGN($U19),ROUND($U19*$V19,2)))) -> 0 | X19: =IF($N19="","",IFERROR(INDEX(VAT_Codes!$H:$H,MATCH($N19,VAT_Codes!$A:$A,0)),"")&"") | Y19: =IF($A19="","",(YEAR($A19)-YEAR(Settings!$C$8))*12+MONTH($A19)-MONTH(Settings!$C$8)+1) -> 1 | Z19: =IF(AND($C19="",$I19="",$J19=""),"",IF($N19="","NO VAT CODE",IF($T19="","UNKNOWN VAT CODE",IF($S19="","MISSING FX RATE",IF(OR($A19<Settings!$C$8,$A19>Settings!$C$9),"OUTSIDE PERIOD",IF(AND(IFERROR(INDEX(VAT_Codes!$E:$E,MATCH($N19,VAT_Codes!$A:$A,0)),"ANY")<>"ANY",$P19=""),"MISSING COUNTERPARTY COUNTRY",IF(AND(IFERROR(INDEX(VAT_Codes!$E:$E,MATCH($N19,VAT_Codes!$A:$A,0)),"ANY")<>"ANY",$P19<>IFERROR(INDEX(VAT_Codes!$E:$E,MATCH($N19,VAT_Codes!$A:$A,0)),"ANY")),"REGION MISMATCH","OK"))))))) -> OK
A20: 46231 | B20: PAY-07 | C20: 1200 | D20: Bank - EUR | E20: July payroll | H20: EUR | I20: -20000 | M20: =IF($C20="","",IFERROR(INDEX(Account_Mapping!$C:$C,MATCH($C20&"",Account_Mapping!$A:$A,0))&"","")) -> NR | N20: =IF($K20<>"",$K20,$M20) -> NR | O20: =IF($F20="","",IFERROR(INDEX(Counterparties!$C:$C,MATCH($F20&"",Counterparties!$A:$A,0))&"","")) | P20: =IF($O20="","",IF($O20="CY","CY",IF(ISNUMBER(MATCH($O20,Lists!$A:$A,0)),"EU","3RD"))) | Q20: =IF($F20="","N",IFERROR(IF(INDEX(Counterparties!$E:$E,MATCH($F20&"",Counterparties!$A:$A,0))="Y","Y","N"),"N")) -> N | R20: =IF(OR($H20="",$H20="EUR"),1,IFERROR(INDEX(FX_Rates!$D:$D,MATCH($H20,FX_Rates!$A:$A,0)),"")) -> 1 | S20: =IF(AND($I20="",$J20=""),"",IF($J20<>"",$J20,IF(OR($R20="",$R20=0),"",ROUND($I20/$R20,2)))) -> -20000 | T20: =IF($N20="","",IFERROR(INDEX(VAT_Codes!$C:$C,MATCH($N20,VAT_Codes!$A:$A,0)),"")&"") -> None | U20: =IF(OR($S20="",$T20="",$T20="None"),0,IF($T20="Output",-$S20,$S20)) -> 0 | V20: =IF($N20="",0,IFERROR(INDEX(VAT_Codes!$D:$D,MATCH($N20,VAT_Codes!$A:$A,0)),0)) -> 0 | W20: =IF($U20=0,0,IF(IFERROR(INDEX(VAT_Codes!$F:$F,MATCH($N20,VAT_Codes!$A:$A,0)),"N")="Y",$U20,IF($L20<>"",ROUND(ABS($L20)/IF(OR($R20="",$R20=0),1,$R20),2)*SIGN($U20),ROUND($U20*$V20,2)))) -> 0 | X20: =IF($N20="","",IFERROR(INDEX(VAT_Codes!$H:$H,MATCH($N20,VAT_Codes!$A:$A,0)),"")&"") | Y20: =IF($A20="","",(YEAR($A20)-YEAR(Settings!$C$8))*12+MONTH($A20)-MONTH(Settings!$C$8)+1) -> 1 | Z20: =IF(AND($C20="",$I20="",$J20=""),"",IF($N20="","NO VAT CODE",IF($T20="","UNKNOWN VAT CODE",IF($S20="","MISSING FX RATE",IF(OR($A20<Settings!$C$8,$A20>Settings!$C$9),"OUTSIDE PERIOD",IF(AND(IFERROR(INDEX(VAT_Codes!$E:$E,MATCH($N20,VAT_Codes!$A:$A,0)),"ANY")<>"ANY",$P20=""),"MISSING COUNTERPARTY COUNTRY",IF(AND(IFERROR(INDEX(VAT_Codes!$E:$E,MATCH($N20,VAT_Codes!$A:$A,0)),"ANY")<>"ANY",$P20<>IFERROR(INDEX(VAT_Codes!$E:$E,MATCH($N20,VAT_Codes!$A:$A,0)),"ANY")),"REGION MISMATCH","OK"))))))) -> OK
M21: =IF($C21="","",IFERROR(INDEX(Account_Mapping!$C:$C,MATCH($C21&"",Account_Mapping!$A:$A,0))&"","")) | N21: =IF($K21<>"",$K21,$M21) | O21: =IF($F21="","",IFERROR(INDEX(Counterparties!$C:$C,MATCH($F21&"",Counterparties!$A:$A,0))&"","")) | P21: =IF($O21="","",IF($O21="CY","CY",IF(ISNUMBER(MATCH($O21,Lists!$A:$A,0)),"EU","3RD"))) | Q21: =IF($F21="","N",IFERROR(IF(INDEX(Counterparties!$E:$E,MATCH($F21&"",Counterparties!$A:$A,0))="Y","Y","N"),"N")) -> N | R21: =IF(OR($H21="",$H21="EUR"),1,IFERROR(INDEX(FX_Rates!$D:$D,MATCH($H21,FX_Rates!$A:$A,0)),"")) -> 1 | S21: =IF(AND($I21="",$J21=""),"",IF($J21<>"",$J21,IF(OR($R21="",$R21=0),"",ROUND($I21/$R21,2)))) | T21: =IF($N21="","",IFERROR(INDEX(VAT_Codes!$C:$C,MATCH($N21,VAT_Codes!$A:$A,0)),"")&"") | U21: =IF(OR($S21="",$T21="",$T21="None"),0,IF($T21="Output",-$S21,$S21)) -> 0 | V21: =IF($N21="",0,IFERROR(INDEX(VAT_Codes!$D:$D,MATCH($N21,VAT_Codes!$A:$A,0)),0)) -> 0 | W21: =IF($U21=0,0,IF(IFERROR(INDEX(VAT_Codes!$F:$F,MATCH($N21,VAT_Codes!$A:$A,0)),"N")="Y",$U21,IF($L21<>"",ROUND(ABS($L21)/IF(OR($R21="",$R21=0),1,$R21),2)*SIGN($U21),ROUND($U21*$V21,2)))) -> 0 | X21: =IF($N21="","",IFERROR(INDEX(VAT_Codes!$H:$H,MATCH($N21,VAT_Codes!$A:$A,0)),"")&"") | Y21: =IF($A21="","",(YEAR($A21)-YEAR(Settings!$C$8))*12+MONTH($A21)-MONTH(Settings!$C$8)+1) | Z21: =IF(AND($C21="",$I21="",$J21=""),"",IF($N21="","NO VAT CODE",IF($T21="","UNKNOWN VAT CODE",IF($S21="","MISSING FX RATE",IF(OR($A21<Settings!$C$8,$A21>Settings!$C$9),"OUTSIDE PERIOD",IF(AND(IFERROR(INDEX(VAT_Codes!$E:$E,MATCH($N21,VAT_Codes!$A:$A,0)),"ANY")<>"ANY",$P21=""),"MISSING COUNTERPARTY COUNTRY",IF(AND(IFERROR(INDEX(VAT_Codes!$E:$E,MATCH($N21,VAT_Codes!$A:$A,0)),"ANY")<>"ANY",$P21<>IFERROR(INDEX(VAT_Codes!$E:$E,MATCH($N21,VAT_Codes!$A:$A,0)),"ANY")),"REGION MISMATCH","OK")))))))
M22: =IF($C22="","",IFERROR(INDEX(Account_Mapping!$C:$C,MATCH($C22&"",Account_Mapping!$A:$A,0))&"","")) | N22: =IF($K22<>"",$K22,$M22) | O22: =IF($F22="","",IFERROR(INDEX(Counterparties!$C:$C,MATCH($F22&"",Counterparties!$A:$A,0))&"","")) | P22: =IF($O22="","",IF($O22="CY","CY",IF(ISNUMBER(MATCH($O22,Lists!$A:$A,0)),"EU","3RD"))) | Q22: =IF($F22="","N",IFERROR(IF(INDEX(Counterparties!$E:$E,MATCH($F22&"",Counterparties!$A:$A,0))="Y","Y","N"),"N")) -> N | R22: =IF(OR($H22="",$H22="EUR"),1,IFERROR(INDEX(FX_Rates!$D:$D,MATCH($H22,FX_Rates!$A:$A,0)),"")) -> 1 | S22: =IF(AND($I22="",$J22=""),"",IF($J22<>"",$J22,IF(OR($R22="",$R22=0),"",ROUND($I22/$R22,2)))) | T22: =IF($N22="","",IFERROR(INDEX(VAT_Codes!$C:$C,MATCH($N22,VAT_Codes!$A:$A,0)),"")&"") | U22: =IF(OR($S22="",$T22="",$T22="None"),0,IF($T22="Output",-$S22,$S22)) -> 0 | V22: =IF($N22="",0,IFERROR(INDEX(VAT_Codes!$D:$D,MATCH($N22,VAT_Codes!$A:$A,0)),0)) -> 0 | W22: =IF($U22=0,0,IF(IFERROR(INDEX(VAT_Codes!$F:$F,MATCH($N22,VAT_Codes!$A:$A,0)),"N")="Y",$U22,IF($L22<>"",ROUND(ABS($L22)/IF(OR($R22="",$R22=0),1,$R22),2)*SIGN($U22),ROUND($U22*$V22,2)))) -> 0 | X22: =IF($N22="","",IFERROR(INDEX(VAT_Codes!$H:$H,MATCH($N22,VAT_Codes!$A:$A,0)),"")&"") | Y22: =IF($A22="","",(YEAR($A22)-YEAR(Settings!$C$8))*12+MONTH($A22)-MONTH(Settings!$C$8)+1) | Z22: =IF(AND($C22="",$I22="",$J22=""),"",IF($N22="","NO VAT CODE",IF($T22="","UNKNOWN VAT CODE",IF($S22="","MISSING FX RATE",IF(OR($A22<Settings!$C$8,$A22>Settings!$C$9),"OUTSIDE PERIOD",IF(AND(IFERROR(INDEX(VAT_Codes!$E:$E,MATCH($N22,VAT_Codes!$A:$A,0)),"ANY")<>"ANY",$P22=""),"MISSING COUNTERPARTY COUNTRY",IF(AND(IFERROR(INDEX(VAT_Codes!$E:$E,MATCH($N22,VAT_Codes!$A:$A,0)),"ANY")<>"ANY",$P22<>IFERROR(INDEX(VAT_Codes!$E:$E,MATCH($N22,VAT_Codes!$A:$A,0)),"ANY")),"REGION MISMATCH","OK")))))))
M23: =IF($C23="","",IFERROR(INDEX(Account_Mapping!$C:$C,MATCH($C23&"",Account_Mapping!$A:$A,0))&"","")) | N23: =IF($K23<>"",$K23,$M23) | O23: =IF($F23="","",IFERROR(INDEX(Counterparties!$C:$C,MATCH($F23&"",Counterparties!$A:$A,0))&"","")) | P23: =IF($O23="","",IF($O23="CY","CY",IF(ISNUMBER(MATCH($O23,Lists!$A:$A,0)),"EU","3RD"))) | Q23: =IF($F23="","N",IFERROR(IF(INDEX(Counterparties!$E:$E,MATCH($F23&"",Counterparties!$A:$A,0))="Y","Y","N"),"N")) -> N | R23: =IF(OR($H23="",$H23="EUR"),1,IFERROR(INDEX(FX_Rates!$D:$D,MATCH($H23,FX_Rates!$A:$A,0)),"")) -> 1 | S23: =IF(AND($I23="",$J23=""),"",IF($J23<>"",$J23,IF(OR($R23="",$R23=0),"",ROUND($I23/$R23,2)))) | T23: =IF($N23="","",IFERROR(INDEX(VAT_Codes!$C:$C,MATCH($N23,VAT_Codes!$A:$A,0)),"")&"") | U23: =IF(OR($S23="",$T23="",$T23="None"),0,IF($T23="Output",-$S23,$S23)) -> 0 | V23: =IF($N23="",0,IFERROR(INDEX(VAT_Codes!$D:$D,MATCH($N23,VAT_Codes!$A:$A,0)),0)) -> 0 | W23: =IF($U23=0,0,IF(IFERROR(INDEX(VAT_Codes!$F:$F,MATCH($N23,VAT_Codes!$A:$A,0)),"N")="Y",$U23,IF($L23<>"",ROUND(ABS($L23)/IF(OR($R23="",$R23=0),1,$R23),2)*SIGN($U23),ROUND($U23*$V23,2)))) -> 0 | X23: =IF($N23="","",IFERROR(INDEX(VAT_Codes!$H:$H,MATCH($N23,VAT_Codes!$A:$A,0)),"")&"") | Y23: =IF($A23="","",(YEAR($A23)-YEAR(Settings!$C$8))*12+MONTH($A23)-MONTH(Settings!$C$8)+1) | Z23: =IF(AND($C23="",$I23="",$J23=""),"",IF($N23="","NO VAT CODE",IF($T23="","UNKNOWN VAT CODE",IF($S23="","MISSING FX RATE",IF(OR($A23<Settings!$C$8,$A23>Settings!$C$9),"OUTSIDE PERIOD",IF(AND(IFERROR(INDEX(VAT_Codes!$E:$E,MATCH($N23,VAT_Codes!$A:$A,0)),"ANY")<>"ANY",$P23=""),"MISSING COUNTERPARTY COUNTRY",IF(AND(IFERROR(INDEX(VAT_Codes!$E:$E,MATCH($N23,VAT_Codes!$A:$A,0)),"ANY")<>"ANY",$P23<>IFERROR(INDEX(VAT_Codes!$E:$E,MATCH($N23,VAT_Codes!$A:$A,0)),"ANY")),"REGION MISMATCH","OK")))))))
M24: =IF($C24="","",IFERROR(INDEX(Account_Mapping!$C:$C,MATCH($C24&"",Account_Mapping!$A:$A,0))&"","")) | N24: =IF($K24<>"",$K24,$M24) | O24: =IF($F24="","",IFERROR(INDEX(Counterparties!$C:$C,MATCH($F24&"",Counterparties!$A:$A,0))&"","")) | P24: =IF($O24="","",IF($O24="CY","CY",IF(ISNUMBER(MATCH($O24,Lists!$A:$A,0)),"EU","3RD"))) | Q24: =IF($F24="","N",IFERROR(IF(INDEX(Counterparties!$E:$E,MATCH($F24&"",Counterparties!$A:$A,0))="Y","Y","N"),"N")) -> N | R24: =IF(OR($H24="",$H24="EUR"),1,IFERROR(INDEX(FX_Rates!$D:$D,MATCH($H24,FX_Rates!$A:$A,0)),"")) -> 1 | S24: =IF(AND($I24="",$J24=""),"",IF($J24<>"",$J24,IF(OR($R24="",$R24=0),"",ROUND($I24/$R24,2)))) | T24: =IF($N24="","",IFERROR(INDEX(VAT_Codes!$C:$C,MATCH($N24,VAT_Codes!$A:$A,0)),"")&"") | U24: =IF(OR($S24="",$T24="",$T24="None"),0,IF($T24="Output",-$S24,$S24)) -> 0 | V24: =IF($N24="",0,IFERROR(INDEX(VAT_Codes!$D:$D,MATCH($N24,VAT_Codes!$A:$A,0)),0)) -> 0 | W24: =IF($U24=0,0,IF(IFERROR(INDEX(VAT_Codes!$F:$F,MATCH($N24,VAT_Codes!$A:$A,0)),"N")="Y",$U24,IF($L24<>"",ROUND(ABS($L24)/IF(OR($R24="",$R24=0),1,$R24),2)*SIGN($U24),ROUND($U24*$V24,2)))) -> 0 | X24: =IF($N24="","",IFERROR(INDEX(VAT_Codes!$H:$H,MATCH($N24,VAT_Codes!$A:$A,0)),"")&"") | Y24: =IF($A24="","",(YEAR($A24)-YEAR(Settings!$C$8))*12+MONTH($A24)-MONTH(Settings!$C$8)+1) | Z24: =IF(AND($C24="",$I24="",$J24=""),"",IF($N24="","NO VAT CODE",IF($T24="","UNKNOWN VAT CODE",IF($S24="","MISSING FX RATE",IF(OR($A24<Settings!$C$8,$A24>Settings!$C$9),"OUTSIDE PERIOD",IF(AND(IFERROR(INDEX(VAT_Codes!$E:$E,MATCH($N24,VAT_Codes!$A:$A,0)),"ANY")<>"ANY",$P24=""),"MISSING COUNTERPARTY COUNTRY",IF(AND(IFERROR(INDEX(VAT_Codes!$E:$E,MATCH($N24,VAT_Codes!$A:$A,0)),"ANY")<>"ANY",$P24<>IFERROR(INDEX(VAT_Codes!$E:$E,MATCH($N24,VAT_Codes!$A:$A,0)),"ANY")),"REGION MISMATCH","OK")))))))
M25: =IF($C25="","",IFERROR(INDEX(Account_Mapping!$C:$C,MATCH($C25&"",Account_Mapping!$A:$A,0))&"","")) | N25: =IF($K25<>"",$K25,$M25) | O25: =IF($F25="","",IFERROR(INDEX(Counterparties!$C:$C,MATCH($F25&"",Counterparties!$A:$A,0))&"","")) | P25: =IF($O25="","",IF($O25="CY","CY",IF(ISNUMBER(MATCH($O25,Lists!$A:$A,0)),"EU","3RD"))) | Q25: =IF($F25="","N",IFERROR(IF(INDEX(Counterparties!$E:$E,MATCH($F25&"",Counterparties!$A:$A,0))="Y","Y","N"),"N")) -> N | R25: =IF(OR($H25="",$H25="EUR"),1,IFERROR(INDEX(FX_Rates!$D:$D,MATCH($H25,FX_Rates!$A:$A,0)),"")) -> 1 | S25: =IF(AND($I25="",$J25=""),"",IF($J25<>"",$J25,IF(OR($R25="",$R25=0),"",ROUND($I25/$R25,2)))) | T25: =IF($N25="","",IFERROR(INDEX(VAT_Codes!$C:$C,MATCH($N25,VAT_Codes!$A:$A,0)),"")&"") | U25: =IF(OR($S25="",$T25="",$T25="None"),0,IF($T25="Output",-$S25,$S25)) -> 0 | V25: =IF($N25="",0,IFERROR(INDEX(VAT_Codes!$D:$D,MATCH($N25,VAT_Codes!$A:$A,0)),0)) -> 0 | W25: =IF($U25=0,0,IF(IFERROR(INDEX(VAT_Codes!$F:$F,MATCH($N25,VAT_Codes!$A:$A,0)),"N")="Y",$U25,IF($L25<>"",ROUND(ABS($L25)/IF(OR($R25="",$R25=0),1,$R25),2)*SIGN($U25),ROUND($U25*$V25,2)))) -> 0 | X25: =IF($N25="","",IFERROR(INDEX(VAT_Codes!$H:$H,MATCH($N25,VAT_Codes!$A:$A,0)),"")&"") | Y25: =IF($A25="","",(YEAR($A25)-YEAR(Settings!$C$8))*12+MONTH($A25)-MONTH(Settings!$C$8)+1) | Z25: =IF(AND($C25="",$I25="",$J25=""),"",IF($N25="","NO VAT CODE",IF($T25="","UNKNOWN VAT CODE",IF($S25="","MISSING FX RATE",IF(OR($A25<Settings!$C$8,$A25>Settings!$C$9),"OUTSIDE PERIOD",IF(AND(IFERROR(INDEX(VAT_Codes!$E:$E,MATCH($N25,VAT_Codes!$A:$A,0)),"ANY")<>"ANY",$P25=""),"MISSING COUNTERPARTY COUNTRY",IF(AND(IFERROR(INDEX(VAT_Codes!$E:$E,MATCH($N25,VAT_Codes!$A:$A,0)),"ANY")<>"ANY",$P25<>IFERROR(INDEX(VAT_Codes!$E:$E,MATCH($N25,VAT_Codes!$A:$A,0)),"ANY")),"REGION MISMATCH","OK")))))))
M26: =IF($C26="","",IFERROR(INDEX(Account_Mapping!$C:$C,MATCH($C26&"",Account_Mapping!$A:$A,0))&"","")) | N26: =IF($K26<>"",$K26,$M26) | O26: =IF($F26="","",IFERROR(INDEX(Counterparties!$C:$C,MATCH($F26&"",Counterparties!$A:$A,0))&"","")) | P26: =IF($O26="","",IF($O26="CY","CY",IF(ISNUMBER(MATCH($O26,Lists!$A:$A,0)),"EU","3RD"))) | Q26: =IF($F26="","N",IFERROR(IF(INDEX(Counterparties!$E:$E,MATCH($F26&"",Counterparties!$A:$A,0))="Y","Y","N"),"N")) -> N | R26: =IF(OR($H26="",$H26="EUR"),1,IFERROR(INDEX(FX_Rates!$D:$D,MATCH($H26,FX_Rates!$A:$A,0)),"")) -> 1 | S26: =IF(AND($I26="",$J26=""),"",IF($J26<>"",$J26,IF(OR($R26="",$R26=0),"",ROUND($I26/$R26,2)))) | T26: =IF($N26="","",IFERROR(INDEX(VAT_Codes!$C:$C,MATCH($N26,VAT_Codes!$A:$A,0)),"")&"") | U26: =IF(OR($S26="",$T26="",$T26="None"),0,IF($T26="Output",-$S26,$S26)) -> 0 | V26: =IF($N26="",0,IFERROR(INDEX(VAT_Codes!$D:$D,MATCH($N26,VAT_Codes!$A:$A,0)),0)) -> 0 | W26: =IF($U26=0,0,IF(IFERROR(INDEX(VAT_Codes!$F:$F,MATCH($N26,VAT_Codes!$A:$A,0)),"N")="Y",$U26,IF($L26<>"",ROUND(ABS($L26)/IF(OR($R26="",$R26=0),1,$R26),2)*SIGN($U26),ROUND($U26*$V26,2)))) -> 0 | X26: =IF($N26="","",IFERROR(INDEX(VAT_Codes!$H:$H,MATCH($N26,VAT_Codes!$A:$A,0)),"")&"") | Y26: =IF($A26="","",(YEAR($A26)-YEAR(Settings!$C$8))*12+MONTH($A26)-MONTH(Settings!$C$8)+1) | Z26: =IF(AND($C26="",$I26="",$J26=""),"",IF($N26="","NO VAT CODE",IF($T26="","UNKNOWN VAT CODE",IF($S26="","MISSING FX RATE",IF(OR($A26<Settings!$C$8,$A26>Settings!$C$9),"OUTSIDE PERIOD",IF(AND(IFERROR(INDEX(VAT_Codes!$E:$E,MATCH($N26,VAT_Codes!$A:$A,0)),"ANY")<>"ANY",$P26=""),"MISSING COUNTERPARTY COUNTRY",IF(AND(IFERROR(INDEX(VAT_Codes!$E:$E,MATCH($N26,VAT_Codes!$A:$A,0)),"ANY")<>"ANY",$P26<>IFERROR(INDEX(VAT_Codes!$E:$E,MATCH($N26,VAT_Codes!$A:$A,0)),"ANY")),"REGION MISMATCH","OK")))))))
M27: =IF($C27="","",IFERROR(INDEX(Account_Mapping!$C:$C,MATCH($C27&"",Account_Mapping!$A:$A,0))&"","")) | N27: =IF($K27<>"",$K27,$M27) | O27: =IF($F27="","",IFERROR(INDEX(Counterparties!$C:$C,MATCH($F27&"",Counterparties!$A:$A,0))&"","")) | P27: =IF($O27="","",IF($O27="CY","CY",IF(ISNUMBER(MATCH($O27,Lists!$A:$A,0)),"EU","3RD"))) | Q27: =IF($F27="","N",IFERROR(IF(INDEX(Counterparties!$E:$E,MATCH($F27&"",Counterparties!$A:$A,0))="Y","Y","N"),"N")) -> N | R27: =IF(OR($H27="",$H27="EUR"),1,IFERROR(INDEX(FX_Rates!$D:$D,MATCH($H27,FX_Rates!$A:$A,0)),"")) -> 1 | S27: =IF(AND($I27="",$J27=""),"",IF($J27<>"",$J27,IF(OR($R27="",$R27=0),"",ROUND($I27/$R27,2)))) | T27: =IF($N27="","",IFERROR(INDEX(VAT_Codes!$C:$C,MATCH($N27,VAT_Codes!$A:$A,0)),"")&"") | U27: =IF(OR($S27="",$T27="",$T27="None"),0,IF($T27="Output",-$S27,$S27)) -> 0 | V27: =IF($N27="",0,IFERROR(INDEX(VAT_Codes!$D:$D,MATCH($N27,VAT_Codes!$A:$A,0)),0)) -> 0 | W27: =IF($U27=0,0,IF(IFERROR(INDEX(VAT_Codes!$F:$F,MATCH($N27,VAT_Codes!$A:$A,0)),"N")="Y",$U27,IF($L27<>"",ROUND(ABS($L27)/IF(OR($R27="",$R27=0),1,$R27),2)*SIGN($U27),ROUND($U27*$V27,2)))) -> 0 | X27: =IF($N27="","",IFERROR(INDEX(VAT_Codes!$H:$H,MATCH($N27,VAT_Codes!$A:$A,0)),"")&"") | Y27: =IF($A27="","",(YEAR($A27)-YEAR(Settings!$C$8))*12+MONTH($A27)-MONTH(Settings!$C$8)+1) | Z27: =IF(AND($C27="",$I27="",$J27=""),"",IF($N27="","NO VAT CODE",IF($T27="","UNKNOWN VAT CODE",IF($S27="","MISSING FX RATE",IF(OR($A27<Settings!$C$8,$A27>Settings!$C$9),"OUTSIDE PERIOD",IF(AND(IFERROR(INDEX(VAT_Codes!$E:$E,MATCH($N27,VAT_Codes!$A:$A,0)),"ANY")<>"ANY",$P27=""),"MISSING COUNTERPARTY COUNTRY",IF(AND(IFERROR(INDEX(VAT_Codes!$E:$E,MATCH($N27,VAT_Codes!$A:$A,0)),"ANY")<>"ANY",$P27<>IFERROR(INDEX(VAT_Codes!$E:$E,MATCH($N27,VAT_Codes!$A:$A,0)),"ANY")),"REGION MISMATCH","OK")))))))
M28: =IF($C28="","",IFERROR(INDEX(Account_Mapping!$C:$C,MATCH($C28&"",Account_Mapping!$A:$A,0))&"","")) | N28: =IF($K28<>"",$K28,$M28) | O28: =IF($F28="","",IFERROR(INDEX(Counterparties!$C:$C,MATCH($F28&"",Counterparties!$A:$A,0))&"","")) | P28: =IF($O28="","",IF($O28="CY","CY",IF(ISNUMBER(MATCH($O28,Lists!$A:$A,0)),"EU","3RD"))) | Q28: =IF($F28="","N",IFERROR(IF(INDEX(Counterparties!$E:$E,MATCH($F28&"",Counterparties!$A:$A,0))="Y","Y","N"),"N")) -> N | R28: =IF(OR($H28="",$H28="EUR"),1,IFERROR(INDEX(FX_Rates!$D:$D,MATCH($H28,FX_Rates!$A:$A,0)),"")) -> 1 | S28: =IF(AND($I28="",$J28=""),"",IF($J28<>"",$J28,IF(OR($R28="",$R28=0),"",ROUND($I28/$R28,2)))) | T28: =IF($N28="","",IFERROR(INDEX(VAT_Codes!$C:$C,MATCH($N28,VAT_Codes!$A:$A,0)),"")&"") | U28: =IF(OR($S28="",$T28="",$T28="None"),0,IF($T28="Output",-$S28,$S28)) -> 0 | V28: =IF($N28="",0,IFERROR(INDEX(VAT_Codes!$D:$D,MATCH($N28,VAT_Codes!$A:$A,0)),0)) -> 0 | W28: =IF($U28=0,0,IF(IFERROR(INDEX(VAT_Codes!$F:$F,MATCH($N28,VAT_Codes!$A:$A,0)),"N")="Y",$U28,IF($L28<>"",ROUND(ABS($L28)/IF(OR($R28="",$R28=0),1,$R28),2)*SIGN($U28),ROUND($U28*$V28,2)))) -> 0 | X28: =IF($N28="","",IFERROR(INDEX(VAT_Codes!$H:$H,MATCH($N28,VAT_Codes!$A:$A,0)),"")&"") | Y28: =IF($A28="","",(YEAR($A28)-YEAR(Settings!$C$8))*12+MONTH($A28)-MONTH(Settings!$C$8)+1) | Z28: =IF(AND($C28="",$I28="",$J28=""),"",IF($N28="","NO VAT CODE",IF($T28="","UNKNOWN VAT CODE",IF($S28="","MISSING FX RATE",IF(OR($A28<Settings!$C$8,$A28>Settings!$C$9),"OUTSIDE PERIOD",IF(AND(IFERROR(INDEX(VAT_Codes!$E:$E,MATCH($N28,VAT_Codes!$A:$A,0)),"ANY")<>"ANY",$P28=""),"MISSING COUNTERPARTY COUNTRY",IF(AND(IFERROR(INDEX(VAT_Codes!$E:$E,MATCH($N28,VAT_Codes!$A:$A,0)),"ANY")<>"ANY",$P28<>IFERROR(INDEX(VAT_Codes!$E:$E,MATCH($N28,VAT_Codes!$A:$A,0)),"ANY")),"REGION MISMATCH","OK")))))))
M29: =IF($C29="","",IFERROR(INDEX(Account_Mapping!$C:$C,MATCH($C29&"",Account_Mapping!$A:$A,0))&"","")) | N29: =IF($K29<>"",$K29,$M29) | O29: =IF($F29="","",IFERROR(INDEX(Counterparties!$C:$C,MATCH($F29&"",Counterparties!$A:$A,0))&"","")) | P29: =IF($O29="","",IF($O29="CY","CY",IF(ISNUMBER(MATCH($O29,Lists!$A:$A,0)),"EU","3RD"))) | Q29: =IF($F29="","N",IFERROR(IF(INDEX(Counterparties!$E:$E,MATCH($F29&"",Counterparties!$A:$A,0))="Y","Y","N"),"N")) -> N | R29: =IF(OR($H29="",$H29="EUR"),1,IFERROR(INDEX(FX_Rates!$D:$D,MATCH($H29,FX_Rates!$A:$A,0)),"")) -> 1 | S29: =IF(AND($I29="",$J29=""),"",IF($J29<>"",$J29,IF(OR($R29="",$R29=0),"",ROUND($I29/$R29,2)))) | T29: =IF($N29="","",IFERROR(INDEX(VAT_Codes!$C:$C,MATCH($N29,VAT_Codes!$A:$A,0)),"")&"") | U29: =IF(OR($S29="",$T29="",$T29="None"),0,IF($T29="Output",-$S29,$S29)) -> 0 | V29: =IF($N29="",0,IFERROR(INDEX(VAT_Codes!$D:$D,MATCH($N29,VAT_Codes!$A:$A,0)),0)) -> 0 | W29: =IF($U29=0,0,IF(IFERROR(INDEX(VAT_Codes!$F:$F,MATCH($N29,VAT_Codes!$A:$A,0)),"N")="Y",$U29,IF($L29<>"",ROUND(ABS($L29)/IF(OR($R29="",$R29=0),1,$R29),2)*SIGN($U29),ROUND($U29*$V29,2)))) -> 0 | X29: =IF($N29="","",IFERROR(INDEX(VAT_Codes!$H:$H,MATCH($N29,VAT_Codes!$A:$A,0)),"")&"") | Y29: =IF($A29="","",(YEAR($A29)-YEAR(Settings!$C$8))*12+MONTH($A29)-MONTH(Settings!$C$8)+1) | Z29: =IF(AND($C29="",$I29="",$J29=""),"",IF($N29="","NO VAT CODE",IF($T29="","UNKNOWN VAT CODE",IF($S29="","MISSING FX RATE",IF(OR($A29<Settings!$C$8,$A29>Settings!$C$9),"OUTSIDE PERIOD",IF(AND(IFERROR(INDEX(VAT_Codes!$E:$E,MATCH($N29,VAT_Codes!$A:$A,0)),"ANY")<>"ANY",$P29=""),"MISSING COUNTERPARTY COUNTRY",IF(AND(IFERROR(INDEX(VAT_Codes!$E:$E,MATCH($N29,VAT_Codes!$A:$A,0)),"ANY")<>"ANY",$P29<>IFERROR(INDEX(VAT_Codes!$E:$E,MATCH($N29,VAT_Codes!$A:$A,0)),"ANY")),"REGION MISMATCH","OK")))))))
M30: =IF($C30="","",IFERROR(INDEX(Account_Mapping!$C:$C,MATCH($C30&"",Account_Mapping!$A:$A,0))&"","")) | N30: =IF($K30<>"",$K30,$M30) | O30: =IF($F30="","",IFERROR(INDEX(Counterparties!$C:$C,MATCH($F30&"",Counterparties!$A:$A,0))&"","")) | P30: =IF($O30="","",IF($O30="CY","CY",IF(ISNUMBER(MATCH($O30,Lists!$A:$A,0)),"EU","3RD"))) | Q30: =IF($F30="","N",IFERROR(IF(INDEX(Counterparties!$E:$E,MATCH($F30&"",Counterparties!$A:$A,0))="Y","Y","N"),"N")) -> N | R30: =IF(OR($H30="",$H30="EUR"),1,IFERROR(INDEX(FX_Rates!$D:$D,MATCH($H30,FX_Rates!$A:$A,0)),"")) -> 1 | S30: =IF(AND($I30="",$J30=""),"",IF($J30<>"",$J30,IF(OR($R30="",$R30=0),"",ROUND($I30/$R30,2)))) | T30: =IF($N30="","",IFERROR(INDEX(VAT_Codes!$C:$C,MATCH($N30,VAT_Codes!$A:$A,0)),"")&"") | U30: =IF(OR($S30="",$T30="",$T30="None"),0,IF($T30="Output",-$S30,$S30)) -> 0 | V30: =IF($N30="",0,IFERROR(INDEX(VAT_Codes!$D:$D,MATCH($N30,VAT_Codes!$A:$A,0)),0)) -> 0 | W30: =IF($U30=0,0,IF(IFERROR(INDEX(VAT_Codes!$F:$F,MATCH($N30,VAT_Codes!$A:$A,0)),"N")="Y",$U30,IF($L30<>"",ROUND(ABS($L30)/IF(OR($R30="",$R30=0),1,$R30),2)*SIGN($U30),ROUND($U30*$V30,2)))) -> 0 | X30: =IF($N30="","",IFERROR(INDEX(VAT_Codes!$H:$H,MATCH($N30,VAT_Codes!$A:$A,0)),"")&"") | Y30: =IF($A30="","",(YEAR($A30)-YEAR(Settings!$C$8))*12+MONTH($A30)-MONTH(Settings!$C$8)+1) | Z30: =IF(AND($C30="",$I30="",$J30=""),"",IF($N30="","NO VAT CODE",IF($T30="","UNKNOWN VAT CODE",IF($S30="","MISSING FX RATE",IF(OR($A30<Settings!$C$8,$A30>Settings!$C$9),"OUTSIDE PERIOD",IF(AND(IFERROR(INDEX(VAT_Codes!$E:$E,MATCH($N30,VAT_Codes!$A:$A,0)),"ANY")<>"ANY",$P30=""),"MISSING COUNTERPARTY COUNTRY",IF(AND(IFERROR(INDEX(VAT_Codes!$E:$E,MATCH($N30,VAT_Codes!$A:$A,0)),"ANY")<>"ANY",$P30<>IFERROR(INDEX(VAT_Codes!$E:$E,MATCH($N30,VAT_Codes!$A:$A,0)),"ANY")),"REGION MISMATCH","OK")))))))
M31: =IF($C31="","",IFERROR(INDEX(Account_Mapping!$C:$C,MATCH($C31&"",Account_Mapping!$A:$A,0))&"","")) | N31: =IF($K31<>"",$K31,$M31) | O31: =IF($F31="","",IFERROR(INDEX(Counterparties!$C:$C,MATCH($F31&"",Counterparties!$A:$A,0))&"","")) | P31: =IF($O31="","",IF($O31="CY","CY",IF(ISNUMBER(MATCH($O31,Lists!$A:$A,0)),"EU","3RD"))) | Q31: =IF($F31="","N",IFERROR(IF(INDEX(Counterparties!$E:$E,MATCH($F31&"",Counterparties!$A:$A,0))="Y","Y","N"),"N")) -> N | R31: =IF(OR($H31="",$H31="EUR"),1,IFERROR(INDEX(FX_Rates!$D:$D,MATCH($H31,FX_Rates!$A:$A,0)),"")) -> 1 | S31: =IF(AND($I31="",$J31=""),"",IF($J31<>"",$J31,IF(OR($R31="",$R31=0),"",ROUND($I31/$R31,2)))) | T31: =IF($N31="","",IFERROR(INDEX(VAT_Codes!$C:$C,MATCH($N31,VAT_Codes!$A:$A,0)),"")&"") | U31: =IF(OR($S31="",$T31="",$T31="None"),0,IF($T31="Output",-$S31,$S31)) -> 0 | V31: =IF($N31="",0,IFERROR(INDEX(VAT_Codes!$D:$D,MATCH($N31,VAT_Codes!$A:$A,0)),0)) -> 0 | W31: =IF($U31=0,0,IF(IFERROR(INDEX(VAT_Codes!$F:$F,MATCH($N31,VAT_Codes!$A:$A,0)),"N")="Y",$U31,IF($L31<>"",ROUND(ABS($L31)/IF(OR($R31="",$R31=0),1,$R31),2)*SIGN($U31),ROUND($U31*$V31,2)))) -> 0 | X31: =IF($N31="","",IFERROR(INDEX(VAT_Codes!$H:$H,MATCH($N31,VAT_Codes!$A:$A,0)),"")&"") | Y31: =IF($A31="","",(YEAR($A31)-YEAR(Settings!$C$8))*12+MONTH($A31)-MONTH(Settings!$C$8)+1) | Z31: =IF(AND($C31="",$I31="",$J31=""),"",IF($N31="","NO VAT CODE",IF($T31="","UNKNOWN VAT CODE",IF($S31="","MISSING FX RATE",IF(OR($A31<Settings!$C$8,$A31>Settings!$C$9),"OUTSIDE PERIOD",IF(AND(IFERROR(INDEX(VAT_Codes!$E:$E,MATCH($N31,VAT_Codes!$A:$A,0)),"ANY")<>"ANY",$P31=""),"MISSING COUNTERPARTY COUNTRY",IF(AND(IFERROR(INDEX(VAT_Codes!$E:$E,MATCH($N31,VAT_Codes!$A:$A,0)),"ANY")<>"ANY",$P31<>IFERROR(INDEX(VAT_Codes!$E:$E,MATCH($N31,VAT_Codes!$A:$A,0)),"ANY")),"REGION MISMATCH","OK")))))))
M32: =IF($C32="","",IFERROR(INDEX(Account_Mapping!$C:$C,MATCH($C32&"",Account_Mapping!$A:$A,0))&"","")) | N32: =IF($K32<>"",$K32,$M32) | O32: =IF($F32="","",IFERROR(INDEX(Counterparties!$C:$C,MATCH($F32&"",Counterparties!$A:$A,0))&"","")) | P32: =IF($O32="","",IF($O32="CY","CY",IF(ISNUMBER(MATCH($O32,Lists!$A:$A,0)),"EU","3RD"))) | Q32: =IF($F32="","N",IFERROR(IF(INDEX(Counterparties!$E:$E,MATCH($F32&"",Counterparties!$A:$A,0))="Y","Y","N"),"N")) -> N | R32: =IF(OR($H32="",$H32="EUR"),1,IFERROR(INDEX(FX_Rates!$D:$D,MATCH($H32,FX_Rates!$A:$A,0)),"")) -> 1 | S32: =IF(AND($I32="",$J32=""),"",IF($J32<>"",$J32,IF(OR($R32="",$R32=0),"",ROUND($I32/$R32,2)))) | T32: =IF($N32="","",IFERROR(INDEX(VAT_Codes!$C:$C,MATCH($N32,VAT_Codes!$A:$A,0)),"")&"") | U32: =IF(OR($S32="",$T32="",$T32="None"),0,IF($T32="Output",-$S32,$S32)) -> 0 | V32: =IF($N32="",0,IFERROR(INDEX(VAT_Codes!$D:$D,MATCH($N32,VAT_Codes!$A:$A,0)),0)) -> 0 | W32: =IF($U32=0,0,IF(IFERROR(INDEX(VAT_Codes!$F:$F,MATCH($N32,VAT_Codes!$A:$A,0)),"N")="Y",$U32,IF($L32<>"",ROUND(ABS($L32)/IF(OR($R32="",$R32=0),1,$R32),2)*SIGN($U32),ROUND($U32*$V32,2)))) -> 0 | X32: =IF($N32="","",IFERROR(INDEX(VAT_Codes!$H:$H,MATCH($N32,VAT_Codes!$A:$A,0)),"")&"") | Y32: =IF($A32="","",(YEAR($A32)-YEAR(Settings!$C$8))*12+MONTH($A32)-MONTH(Settings!$C$8)+1) | Z32: =IF(AND($C32="",$I32="",$J32=""),"",IF($N32="","NO VAT CODE",IF($T32="","UNKNOWN VAT CODE",IF($S32="","MISSING FX RATE",IF(OR($A32<Settings!$C$8,$A32>Settings!$C$9),"OUTSIDE PERIOD",IF(AND(IFERROR(INDEX(VAT_Codes!$E:$E,MATCH($N32,VAT_Codes!$A:$A,0)),"ANY")<>"ANY",$P32=""),"MISSING COUNTERPARTY COUNTRY",IF(AND(IFERROR(INDEX(VAT_Codes!$E:$E,MATCH($N32,VAT_Codes!$A:$A,0)),"ANY")<>"ANY",$P32<>IFERROR(INDEX(VAT_Codes!$E:$E,MATCH($N32,VAT_Codes!$A:$A,0)),"ANY")),"REGION MISMATCH","OK")))))))
